# Resolved promise
A resolved promise in JavaScript is a promise that has successfully completed its operation and returned a result. When a promise is resolved, it means that the asynchronous operation it represents has finished, and the promise has been fulfilled with a value (the result of that operation).

# Promises in a nutshell:
A promise is an object that represents the eventual completion or failure of an asynchronous operation. It can be in one of three states:

### Pending: 
The promise is still waiting for the async operation to complete (it hasn’t finished yet).
### Fulfilled (resolved): 
The async operation was successful, and the promise is now resolved with a value.
### Rejected:
The async operation failed, and the promise was rejected with an error.
What is a resolved promise?

**A resolved promise is a promise that has successfully completed, meaning the asynchronous operation has finished, and the promise is fulfilled with a value. This value can then be accessed using .then().**

## Example of a resolved promise:
```
const promise = new Promise((resolve, reject) => {
  // Simulate an async operation
  setTimeout(() => {
    resolve("Success!");  // The promise is now resolved with the value "Success!"
  }, 1000);
});

promise.then((result) => {
  console.log(result);  // Logs "Success!" after 1 second
});
```
In this example, the promise starts in a pending state.
After 1 second, resolve("Success!") is called, and the promise is resolved.

Now the promise is fulfilled with the value "Success!", and the .then() function will receive and log this value.

## Why use a resolved promise?
A resolved promise allows you to represent and work with asynchronous code in a cleaner way. When the promise is resolved, it means the operation succeeded, and you can use the value it produces.

### Creating an immediately resolved promise:
You can also create an immediately resolved promise (a promise that is resolved as soon as it is created) using Promise.resolve():

```
const resolvedPromise = Promise.resolve("Immediate Success");

resolvedPromise.then((value) => {
  console.log(value);  // Logs "Immediate Success" instantly
});
```
Here:

Promise.resolve("Immediate Success") creates a promise that is already resolved with the value "Immediate Success".

This is useful if you want to ensure that a function always returns a promise, even if there’s no asynchronous operation involved.

## Example in practical usage:
Let’s say you have a function that may or may not perform an async operation, but you want it to always return a promise. You can use Promise.`resolve()` to ensure that:

```
function getData() {
  // Simulate a synchronous value (data is already available)
  const data = "Hello, World!";
  
  // Wrap the data in a resolved promise
  return Promise.resolve(data);
}

getData().then((data) => {
  console.log(data);  // Logs "Hello, World!"
});
```
`Promise.resolve(data)` ensures that `getData()` always returns a promise, even though in this case, the data was immediately available (synchronous).

## In summary:
A resolved promise is a promise that has successfully completed its operation and is now in the fulfilled state with a value.

You can use `.then()` to handle the value when the promise is resolved.

`Promise.resolve()` creates an immediately resolved promise with a given value.

What is `.then()` in JavaScript?
`.then()` is a method available on a promise that allows you to specify what should happen after the promise is resolved (fulfilled). It is used to handle the result or value returned by the promise once the asynchronous operation is complete.

```
promise.then(onFulfilled, onRejected);
```
**onFulfilled:** A function that gets called if the promise is successfully resolved (fulfilled). It receives the result of the promise.

**onRejected (optional):** A function that gets called if the promise is rejected (failed). It receives the reason for the rejection (typically an error).

Example of using .then():
Here’s a basic example where we use .then() to handle a resolved promise:

javascript
Copy code
const promise = new Promise((resolve, reject) => {
  setTimeout(() => {
    resolve("Data received!");  // Resolve the promise after 1 second
  }, 1000);
});

// Handling the resolved promise
promise.then((result) => {
  console.log(result);  // Logs: "Data received!" after 1 second
});
Promise creation: The promise is created with new Promise((resolve, reject) => {...}).
Inside the promise, after 1 second, resolve("Data received!") is called, meaning the promise is fulfilled.
Using .then(): We use .then() to specify what should happen when the promise is resolved. In this case, it logs "Data received!" to the console.
Chaining .then():
One powerful feature of .then() is that it can be chained. Each .then() returns a new promise, allowing you to perform a series of asynchronous operations one after the other.

Here’s an example where .then() is chained to perform multiple steps:

javascript
Copy code
const promise = new Promise((resolve, reject) => {
  setTimeout(() => {
    resolve(2);  // Resolve the promise with the value 2 after 1 second
  }, 1000);
});

promise
  .then((result) => {
    console.log(result);  // Logs: 2
    return result * 2;    // Return a new value to the next `.then()`
  })
  .then((newResult) => {
    console.log(newResult);  // Logs: 4
    return newResult * 2;    // Return another new value to the next `.then()`
  })
  .then((finalResult) => {
    console.log(finalResult);  // Logs: 8
  });
First .then(): The promise is resolved with 2, so the first .then() logs 2 and returns 2 * 2 = 4.
Second .then(): The value returned from the previous .then() is 4, so it logs 4 and returns 4 * 2 = 8.
Third .then(): The value is now 8, so it logs 8.
Handling errors with .then():
When a promise is rejected (when something goes wrong), you can catch and handle the error using the second argument of .then() or by chaining .catch().

Example using .then() for error handling:
javascript
Copy code
const promise = new Promise((resolve, reject) => {
  setTimeout(() => {
    reject("Something went wrong!");  // Reject the promise after 1 second
  }, 1000);
});

// Handling the rejected promise
promise.then(
  (result) => {
    console.log(result);  // This will not run, as the promise is rejected
  },
  (error) => {
    console.log(error);  // Logs: "Something went wrong!" after 1 second
  }
);
Example using .catch() for error handling:
It’s more common to handle errors with .catch(), as it keeps the code cleaner:

javascript
Copy code
const promise = new Promise((resolve, reject) => {
  setTimeout(() => {
    reject("Something went wrong!");  // Reject the promise after 1 second
  }, 1000);
});

// Handling the error with `.catch()`
promise
  .then((result) => {
    console.log(result);  // This will not run, as the promise is rejected
  })
  .catch((error) => {
    console.log(error);  // Logs: "Something went wrong!" after 1 second
  });
Returning promises inside .then():
One key feature of .then() is that it can return another promise. When this happens, the next .then() in the chain will wait for the new promise to resolve.

Example of returning a promise inside .then():
javascript
Copy code
const getData = () => {
  return new Promise((resolve) => {
    setTimeout(() => {
      resolve("Data from getData");
    }, 1000);
  });
};

const processData = (data) => {
  return new Promise((resolve) => {
    setTimeout(() => {
      resolve(`Processed: ${data}`);
    }, 1000);
  });
};

// Chaining promises
getData()
  .then((data) => {
    console.log(data);  // Logs: "Data from getData"
    return processData(data);  // Returns another promise
  })
  .then((processedData) => {
    console.log(processedData);  // Logs: "Processed: Data from getData"
  });
The first .then() returns another promise from processData().
The second .then() waits for processData to resolve and logs the result.
Summary of .then():
.then() is used to handle the value of a resolved promise.
It takes two arguments: a success handler (for resolved promises) and an optional error handler (for rejected promises).
Chaining: .then() can be chained to handle a series of asynchronous operations in sequence.
Error handling: Errors in the promise chain can be caught with the second argument of .then() or with .catch().
Returning promises: If you return a promise from .then(), the next .then() will wait for that promise to resolve before continuing.
Example Recap with .then() and error handling:
javascript
Copy code
const asyncTask = () => {
  return new Promise((resolve, reject) => {
    setTimeout(() => {
      resolve("Task complete!");
    }, 1000);
  });
};

asyncTask()
  .then((result) => {
    console.log(result);  // Logs: "Task complete!"
    return anotherTask();  // Returns a new promise
  })
  .then((anotherResult) => {
    console.log(anotherResult);  // Logs: result of `anotherTask`
  })
  .catch((error) => {
    console.error("Error:", error);  // Logs any error that occurs in the chain
  });
Key Points:
Chaining: .then() can chain multiple async steps.
Error handling: Use .catch() to handle errors.
Return values: You can return either values or promises from .then(). If a promise is returned, the next .then() waits for it to resolve.